[2023-07-26T23:30:30.388+0000] {taskinstance.py:1103} INFO - Dependencies all met for dep_context=non-requeueable deps ti=<TaskInstance: EPT_DATA_ENG_ETL_V0.1.0.load_data_api_to_s3 manual__2023-07-26T23:30:12.037655+00:00 [queued]>
[2023-07-26T23:30:30.400+0000] {taskinstance.py:1103} INFO - Dependencies all met for dep_context=requeueable deps ti=<TaskInstance: EPT_DATA_ENG_ETL_V0.1.0.load_data_api_to_s3 manual__2023-07-26T23:30:12.037655+00:00 [queued]>
[2023-07-26T23:30:30.401+0000] {taskinstance.py:1308} INFO - Starting attempt 1 of 2
[2023-07-26T23:30:30.421+0000] {taskinstance.py:1327} INFO - Executing <Task(PythonOperator): load_data_api_to_s3> on 2023-07-26 23:30:12.037655+00:00
[2023-07-26T23:30:30.429+0000] {standard_task_runner.py:57} INFO - Started process 259 to run task
[2023-07-26T23:30:30.433+0000] {standard_task_runner.py:84} INFO - Running: ['***', 'tasks', 'run', 'EPT_DATA_ENG_ETL_V0.1.0', 'load_data_api_to_s3', 'manual__2023-07-26T23:30:12.037655+00:00', '--job-id', '5', '--raw', '--subdir', 'DAGS_FOLDER/etl_dag.py', '--cfg-path', '/tmp/tmpvzleumij']
[2023-07-26T23:30:30.437+0000] {standard_task_runner.py:85} INFO - Job 5: Subtask load_data_api_to_s3
[2023-07-26T23:30:30.504+0000] {task_command.py:410} INFO - Running <TaskInstance: EPT_DATA_ENG_ETL_V0.1.0.load_data_api_to_s3 manual__2023-07-26T23:30:12.037655+00:00 [running]> on host 19c02828aadb
[2023-07-26T23:30:30.616+0000] {taskinstance.py:1547} INFO - Exporting env vars: AIRFLOW_CTX_DAG_OWNER='Airflow' AIRFLOW_CTX_DAG_ID='EPT_DATA_ENG_ETL_V0.1.0' AIRFLOW_CTX_TASK_ID='load_data_api_to_s3' AIRFLOW_CTX_EXECUTION_DATE='2023-07-26T23:30:12.037655+00:00' AIRFLOW_CTX_TRY_NUMBER='1' AIRFLOW_CTX_DAG_RUN_ID='manual__2023-07-26T23:30:12.037655+00:00'
[2023-07-26T23:30:30.634+0000] {taskinstance.py:1824} ERROR - Task failed with exception
Traceback (most recent call last):
  File "/home/airflow/.local/lib/python3.7/site-packages/airflow/operators/python.py", line 181, in execute
    return_value = self.execute_callable()
  File "/home/airflow/.local/lib/python3.7/site-packages/airflow/operators/python.py", line 198, in execute_callable
    return self.python_callable(*self.op_args, **self.op_kwargs)
  File "/opt/airflow/dags/utils.py", line 129, in load_api_data_to_s3
    dataframe = pd.read_json(dataframe_json, orient='records')
  File "/home/airflow/.local/lib/python3.7/site-packages/pandas/util/_decorators.py", line 207, in wrapper
    return func(*args, **kwargs)
  File "/home/airflow/.local/lib/python3.7/site-packages/pandas/util/_decorators.py", line 311, in wrapper
    return func(*args, **kwargs)
  File "/home/airflow/.local/lib/python3.7/site-packages/pandas/io/json/_json.py", line 607, in read_json
    encoding_errors=encoding_errors,
  File "/home/airflow/.local/lib/python3.7/site-packages/pandas/io/json/_json.py", line 675, in __init__
    data = self._get_data_from_filepath(filepath_or_buffer)
  File "/home/airflow/.local/lib/python3.7/site-packages/pandas/io/json/_json.py", line 718, in _get_data_from_filepath
    errors=self.encoding_errors,
  File "/home/airflow/.local/lib/python3.7/site-packages/pandas/io/common.py", line 614, in get_handle
    storage_options=storage_options,
  File "/home/airflow/.local/lib/python3.7/site-packages/pandas/io/common.py", line 396, in _get_filepath_or_buffer
    raise ValueError(msg)
ValueError: Invalid file path or buffer object type: <class 'NoneType'>
[2023-07-26T23:30:30.648+0000] {taskinstance.py:1350} INFO - Marking task as UP_FOR_RETRY. dag_id=EPT_DATA_ENG_ETL_V0.1.0, task_id=load_data_api_to_s3, execution_date=20230726T233012, start_date=20230726T233030, end_date=20230726T233030
[2023-07-26T23:30:30.664+0000] {standard_task_runner.py:109} ERROR - Failed to execute job 5 for task load_data_api_to_s3 (Invalid file path or buffer object type: <class 'NoneType'>; 259)
[2023-07-26T23:30:30.687+0000] {local_task_job_runner.py:225} INFO - Task exited with return code 1
[2023-07-26T23:30:30.718+0000] {taskinstance.py:2653} INFO - 0 downstream tasks scheduled from follow-on schedule check
